{"name": "test_return_message", "status": "failed", "statusDetails": {"message": "AssertionError: 值为奇数,应为偶数\nassert 1 == 0\n  +1\n  -0", "trace": "@allure.feature(\"test_assert\")\n    @allure.story(\"exampe_02 指定断言失败返回信息\")\n    def test_return_message():\n        a = 1\n>       assert a % 2 == 0, \"值为奇数,应为偶数\"\nE       AssertionError: 值为奇数,应为偶数\nE       assert 1 == 0\nE         +1\nE         -0\n\ntest_01_assert.py:26: AssertionError"}, "start": 1627038693767, "stop": 1627038693767, "uuid": "a4345063-d77a-461c-b592-fe2dbc752334", "historyId": "65a9dc1a4653ab4a1e8d3b323adb9033", "testCaseId": "6b9a3f2c2bdf6c90a7872d0d26947cfc", "fullName": "test_01_assert#test_return_message", "labels": [{"name": "suite", "value": "test_01_assert"}, {"name": "host", "value": "JULIZHOU-6JV5P"}, {"name": "thread", "value": "19824-MainThread"}, {"name": "framework", "value": "pytest"}, {"name": "language", "value": "cpython3"}, {"name": "package", "value": "test_01_assert"}]}